import fs from 'fs';
import path from 'path';
import {
  getPath,
} from "./130_directory_validate.js";
import {
  getLocalIp,
} from "./133_ip_address_validate.js";
import {
  startUp,  // プログラム起動
  getDebugMode,  // デバッグモード判定
  runSqlReadOnly,  // SQLクエリ実行（読み取り専用）
  runSqlWriteOnly,  // SQLクエリ実行（書き込み専用）
  close,  // バックエンドプログラム終了
  getDB,  // データベースオブジェクトを取得
} from "./127_connect_database_validate.js";
import { setBugMode } from "./128_connect_database.js";


export async function test126() {
    setBugMode(0);    // バグを混入させない（通常動作）
    await _test();  // テストを実行（意図的にバグを混入させない）
    await close();
    let i;
    for ( i = 1; i <= 16; i++ ) {
        setBugMode(i);      // 意図的にバグを混入させる
        try {
            await _test();  // 意図的にバグを混入させてテストを実行
        }
        catch (err) {
            // 意図的に埋め込んだバグを正常に検出できた場合。
            while(true){
                try{
                    // 次のテストに影響を与えないように、データベースを閉じる。
                    await close();
                }
                catch(err) {}
                break;
            }
            continue;
        }
        // 意図的に埋め込んだバグを検出できなかった場合
        setBugMode(0);    // 意図的なバグの発生を止める
        console.log(`レイヤー「connect_database」からバグは見つかりませんでしたが、テストコードが不十分です。意図的に発生させたバグ(bugMode: ${ i })を検出できませんでした。\n\n`);
        return;
    }
    // 意図的に埋め込んだ全てのバグを、正常に検出できた
    setBugMode(0);    // 意図的なバグの発生を止める
    console.log(`レイヤー「connect_database」からバグは見つかりませんでした。また、意図的に${ i-1 }件のバグを発生させたところ、全てのバグを検知できました。\n\n`);
    return;
}


// このレイヤーの動作テストを実行する関数
async function _test(){
    
    await startUp("http://localhost:3000/", true);
    await getDebugMode();
    await close();
    //
    await startUp("http://localhost:3000/", true);
    //
    // わざと再接続
    await startUp("localhost:3000", true);
    //
    await close();

}